Workbook
Name UPDATE: 'Data Sheet'!$E$1

Sheet Profit & Loss
A1: ='Data Sheet'!B1 -> TRENT LTD | H1: =UPDATE | M1: SCREENER.IN
A3: Narration | B3: ='Data Sheet'!B16 -> 42825 | C3: ='Data Sheet'!C16 -> 43190 | D3: ='Data Sheet'!D16 -> 43555 | E3: ='Data Sheet'!E16 -> 43921 | F3: ='Data Sheet'!F16 -> 44286 | G3: ='Data Sheet'!G16 -> 44651 | H3: ='Data Sheet'!H16 -> 45016 | I3: ='Data Sheet'!I16 -> 45382 | ... K3: ='Data Sheet'!K16 -> 46112 | L3: Trailing | M3: Best Case | N3: Worst Case
A4: Sales | B4: ='Data Sheet'!B17 -> 1812.44 | C4: ='Data Sheet'!C17 -> 2157.46 | D4: ='Data Sheet'!D17 -> 2630.24 | E4: ='Data Sheet'!E17 -> 3485.98 | F4: ='Data Sheet'!F17 -> 2592.96 | G4: ='Data Sheet'!G17 -> 4498.02 | H4: ='Data Sheet'!H17 -> 8242.02 | I4: ='Data Sheet'!I17 -> 12375.11 | ... K4: ='Data Sheet'!K17 -> 20074.21 | L4: =SUM(Quarters!H4:K4) -> 20074.21 | M4: =$K4+M23*K4 -> 27008.89 | N4: =$K4+N23*L4 -> 23518.125
A5: Expenses | B5: =SUM('Data Sheet'!B18,'Data Sheet'!B20:B24, -1*'Data Sheet'!B19) -> 1678.91 | C5: =SUM('Data Sheet'!C18,'Data Sheet'!C20:C24, -1*'Data Sheet'!C19) -> 1948.96 | D5: =SUM('Data Sheet'!D18,'Data Sheet'!D20:D24, -1*'Data Sheet'!D19) -> 2389.6 | E5: =SUM('Data Sheet'!E18,'Data Sheet'!E20:E24, -1*'Data Sheet'!E19) -> 2957.01 | F5: =SUM('Data Sheet'!F18,'Data Sheet'!F20:F24, -1*'Data Sheet'!F19) -> 2479.09 | G5: =SUM('Data Sheet'!G18,'Data Sheet'!G20:G24, -1*'Data Sheet'!G19) -> 3903.3 | H5: =SUM('Data Sheet'!H18,'Data Sheet'!H20:H24, -1*'Data Sheet'!H19) -> 7127.87 | I5: =SUM('Data Sheet'!I18,'Data Sheet'!I20:I24, -1*'Data Sheet'!I19) -> 10404.42 | ... K5: =SUM('Data Sheet'!K18,'Data Sheet'!K20:K24, -1*'Data Sheet'!K19) -> 16400.82 | L5: =SUM(Quarters!H5:K5) -> 16418 | M5: =M4-M6 -> 22089.634 | N5: =N4-N6 -> 19944.011
A6: Operating Profit | B6: =B4-B5 -> 133.53 | C6: =C4-C5 -> 208.5 | D6: =D4-D5 -> 240.64 | E6: =E4-E5 -> 528.97 | F6: =F4-F5 -> 113.87 | G6: =G4-G5 -> 594.72 | H6: =H4-H5 -> 1114.15 | I6: =I4-I5 -> 1970.69 | ... K6: =K4-K5 -> 3673.39 | L6: =SUM(Quarters!H6:K6) -> 3656.21 | M6: =M4*M24 -> 4919.2557 | N6: =N4*N24 -> 3574.1143
A7: Other Income | B7: ='Data Sheet'!B25 -> 81.31 | C7: ='Data Sheet'!C25 -> 27.47 | D7: ='Data Sheet'!D25 -> 30.14 | E7: ='Data Sheet'!E25 -> 146.63 | F7: ='Data Sheet'!F25 -> 199.4 | G7: ='Data Sheet'!G25 -> 152.16 | H7: ='Data Sheet'!H25 -> 340.6 | I7: ='Data Sheet'!I25 -> 988.91 | ... K7: ='Data Sheet'!K25 -> 92.63 | L7: =SUM(Quarters!H7:K7) -> 109.81 | M7: 0 | N7: 0
A8: Depreciation | B8: ='Data Sheet'!B26 -> 41.29 | C8: ='Data Sheet'!C26 -> 45.53 | D8: ='Data Sheet'!D26 -> 51.67 | E8: ='Data Sheet'!E26 -> 247.24 | F8: ='Data Sheet'!F26 -> 257.3 | G8: ='Data Sheet'!G26 -> 310.82 | H8: ='Data Sheet'!H26 -> 493.69 | I8: ='Data Sheet'!I26 -> 671.11 | ... K8: ='Data Sheet'!K26 -> 1361.19 | L8: =SUM(Quarters!H8:K8) -> 1361.19 | M8: =+$L8 -> 1361.19 | N8: =+$L8 -> 1361.19
A9: Interest | B9: ='Data Sheet'!B27 -> 45.55 | C9: ='Data Sheet'!C27 -> 43.78 | D9: ='Data Sheet'!D27 -> 50.64 | E9: ='Data Sheet'!E27 -> 263.37 | F9: ='Data Sheet'!F27 -> 260.79 | G9: ='Data Sheet'!G27 -> 324.84 | H9: ='Data Sheet'!H27 -> 408.99 | I9: ='Data Sheet'!I27 -> 367.66 | ... K9: ='Data Sheet'!K27 -> 168.35 | L9: =SUM(Quarters!H9:K9) -> 168.35 | M9: =+$L9 -> 168.35 | N9: =+$L9 -> 168.35
A10: Profit before tax | B10: ='Data Sheet'!B28 -> 128 | C10: ='Data Sheet'!C28 -> 146.66 | D10: ='Data Sheet'!D28 -> 168.47 | E10: ='Data Sheet'!E28 -> 164.99 | F10: ='Data Sheet'!F28 -> -204.82 | G10: ='Data Sheet'!G28 -> 111.22 | H10: ='Data Sheet'!H28 -> 552.07 | I10: ='Data Sheet'!I28 -> 1920.83 | ... K10: ='Data Sheet'!K28 -> 2236.48 | L10: =SUM(Quarters!H10:K10) -> 2236.48 | M10: =M6+M7-SUM(M8:M9) -> 3389.7157 | N10: =N6+N7-SUM(N8:N9) -> 2044.5743
A11: Tax | B11: ='Data Sheet'!B29 -> 43.05 | C11: ='Data Sheet'!C29 -> 59.62 | D11: ='Data Sheet'!D29 -> 73.61 | E11: ='Data Sheet'!E29 -> 59.01 | F11: ='Data Sheet'!F29 -> -23.69 | G11: ='Data Sheet'!G29 -> 76.62 | H11: ='Data Sheet'!H29 -> 158.44 | I11: ='Data Sheet'!I29 -> 443.37 | ... K11: ='Data Sheet'!K29 -> 515.15 | L11: =SUM(Quarters!H11:K11) -> 515.15 | M11: =IF($L10>0,$L11/$L10,0) -> 0.23033964 | N11: =IF($L10>0,$L11/$L10,0) -> 0.23033964
A12: Net profit | B12: ='Data Sheet'!B30 -> 84.86 | C12: ='Data Sheet'!C30 -> 86.97 | D12: ='Data Sheet'!D30 -> 96.96 | E12: ='Data Sheet'!E30 -> 122.85 | F12: ='Data Sheet'!F30 -> -146.17 | G12: ='Data Sheet'!G30 -> 105.83 | H12: ='Data Sheet'!H30 -> 444.63 | I12: ='Data Sheet'!I30 -> 1486.8 | ... K12: ='Data Sheet'!K30 -> 1719.65 | L12: =SUM(Quarters!H12:K12) -> 1719.65 | M12: =M10-M11*M10 -> 2608.9298 | N12: =N10-N11*N10 -> 1573.6278
A13: EPS | B13: =IF('Data Sheet'!B93>0,B12/'Data Sheet'!B93,0) -> 2.5537165 | C13: =IF('Data Sheet'!C93>0,C12/'Data Sheet'!C93,0) -> 2.6172134 | D13: =IF('Data Sheet'!D93>0,D12/'Data Sheet'!D93,0) -> 2.9178453 | E13: =IF('Data Sheet'!E93>0,E12/'Data Sheet'!E93,0) -> 3.4556962 | F13: =IF('Data Sheet'!F93>0,F12/'Data Sheet'!F93,0) -> -4.1116737 | G13: =IF('Data Sheet'!G93>0,G12/'Data Sheet'!G93,0) -> 2.9769339 | H13: =IF('Data Sheet'!H93>0,H12/'Data Sheet'!H93,0) -> 12.507173 | I13: =IF('Data Sheet'!I93>0,I12/'Data Sheet'!I93,0) -> 41.822785 | ... K13: =IF('Data Sheet'!K93>0,K12/'Data Sheet'!K93,0) -> 48.372714 | L13: =IF('Data Sheet'!$B6>0,'Profit & Loss'!L12/'Data Sheet'!$B6,0) -> 48.37442 | M13: =IF('Data Sheet'!$B6>0,'Profit & Loss'!M12/'Data Sheet'!$B6,0) -> 73.390205 | N13: =IF('Data Sheet'!$B6>0,'Profit & Loss'!N12/'Data Sheet'!$B6,0) -> 44.266758
A14: Price to earning | B14: =IF(B15>0,B15/B13,"") -> 104.43602 | C14: =IF(C15>0,C15/C13,"") -> 131.8387 | D14: =IF(D15>0,D15/D13,"") -> 124.02988 | E14: =IF(E15>0,E15/E13,"") -> 140.15989 | F14: =IF(F15>0,F15/F13,"") -> -182.66284 | G14: =IF(G15>0,G15/G13,"") -> 428.46098 | H14: =IF(H15>0,H15/H13,"") -> 109.93292 | I14: =IF(I15>0,I15/I13,"") -> 94.398305 | ... K14: =IF(K15>0,K15/K13,"") -> 68.133452 | L14: =IF(L13>0,L15/L13,0) -> 88.834141 | M14: =M25 -> 93.439948 | N14: =N25 -> 88.834141
A15: Price | B15: ='Data Sheet'!B90 -> 266.7 | C15: ='Data Sheet'!C90 -> 345.05 | D15: ='Data Sheet'!D90 -> 361.9 | E15: ='Data Sheet'!E90 -> 484.35 | F15: ='Data Sheet'!F90 -> 751.05 | G15: ='Data Sheet'!G90 -> 1275.5 | H15: ='Data Sheet'!H90 -> 1374.95 | I15: ='Data Sheet'!I90 -> 3948 | ... K15: ='Data Sheet'!K90 -> 3295.8 | L15: ='Data Sheet'!B8 -> 4297.3 | M15: =M13*M14 -> 6857.5769 | N15: =N13*N14 -> 3932.3994
A17: RATIOS:
A18: Dividend Payout | B18: =IF('Data Sheet'!B30>0, 'Data Sheet'!B31/'Data Sheet'!B30, 0) -> 0.39158614 | C18: =IF('Data Sheet'!C30>0, 'Data Sheet'!C31/'Data Sheet'!C30, 0) -> 0.4393469 | D18: =IF('Data Sheet'!D30>0, 'Data Sheet'!D31/'Data Sheet'!D30, 0) -> 0.44554455 | E18: =IF('Data Sheet'!E30>0, 'Data Sheet'!E31/'Data Sheet'!E30, 0) -> 0.28937729 | F18: =IF('Data Sheet'!F30>0, 'Data Sheet'!F31/'Data Sheet'!F30, 0) -> 0 | G18: =IF('Data Sheet'!G30>0, 'Data Sheet'!G31/'Data Sheet'!G30, 0) -> 0.5711046 | H18: =IF('Data Sheet'!H30>0, 'Data Sheet'!H31/'Data Sheet'!H30, 0) -> 0.17589906 | I18: =IF('Data Sheet'!I30>0, 'Data Sheet'!I31/'Data Sheet'!I30, 0) -> 0.076513317 | ... K18: =IF('Data Sheet'!K30>0, 'Data Sheet'!K31/'Data Sheet'!K30, 0) -> 0.12403687
A19: OPM | B19: =IF(B6>0,B6/B4,0) -> 0.073674163 | C19: =IF(C6>0,C6/C4,0) -> 0.096641421 | D19: =IF(D6>0,D6/D4,0) -> 0.09148975 | E19: =IF(E6>0,E6/E4,0) -> 0.15174212 | F19: =IF(F6>0,F6/F4,0) -> 0.043915062 | G19: =IF(G6>0,G6/G4,0) -> 0.13221818 | H19: =IF(H6>0,H6/H4,0) -> 0.13517924 | I19: =IF(I6>0,I6/I4,0) -> 0.15924626 | ... L19: =IF(L6>0,L6/L4,0) -> 0.18213469
G22: TRENDS: | H22: 10 YEARS | I22: 7 YEARS | J22: 5 YEARS | K22: 3 YEARS | L22: RECENT | M22: BEST | N22: WORST
G23: Sales Growth | H23: =IF(B4=0,"",POWER($K4/B4,1/9)-1) -> 0.30629615 | I23: =IF(D4=0,"",POWER($K4/D4,1/7)-1) -> 0.33687829 | J23: =IF(F4=0,"",POWER($K4/F4,1/5)-1) -> 0.50580429 | K23: =IF(H4=0,"",POWER($K4/H4, 1/3)-1) -> 0.34545218 | L23: =IF(ISERROR(MAX(IF(J4=0,"",(K4-J4)/J4),IF(K4=0,"",(L4-K4)/K4))),"",MAX(IF(J4=0,"",(K4-J4)/J4),IF(K4=0,"",(L4-K4)/K4))) -> 0.1715592 | M23: =MAX(K23:L23) -> 0.34545218 | N23: =MIN(H23:L23) -> 0.1715592
G24: OPM | H24: =IF(SUM(B4:$K$4)=0,"",SUMPRODUCT(B19:$K$19,B4:$K$4)/SUM(B4:$K$4)) -> 0.15197275 | I24: =IF(SUM(E4:$K$4)=0,"",SUMPRODUCT(E19:$K$19,E4:$K$4)/SUM(E4:$K$4)) -> 0.15811827 | J24: =IF(SUM(G4:$K$4)=0,"",SUMPRODUCT(G19:$K$19,G4:$K$4)/SUM(G4:$K$4)) -> 0.16322628 | K24: =IF(SUM(I4:$K$4)=0, "", SUMPRODUCT(I19:$K$19,I4:$K$4)/SUM(I4:$K$4)) -> 0.17070127 | L24: =L19 -> 0.18213469 | M24: =MAX(K24:L24) -> 0.18213469 | N24: =MIN(H24:L24) -> 0.15197275
G25: Price to Earning | H25: =IF(ISERROR(AVERAGEIF(B14:$L14,">0")),"",AVERAGEIF(B14:$L14,">0")) -> 141.26182 | I25: =IF(ISERROR(AVERAGEIF(E14:$L14,">0")),"",AVERAGEIF(E14:$L14,">0")) -> 150.33051 | J25: =IF(ISERROR(AVERAGEIF(G14:$L14,">0")),"",AVERAGEIF(G14:$L14,">0")) -> 152.02561 | K25: =IF(ISERROR(AVERAGEIF(I14:$L14,">0")),"",AVERAGEIF(I14:$L14,">0")) -> 93.439948 | L25: =L14 -> 88.834141 | M25: =MAX(K25:L25) -> 93.439948 | N25: =MIN(H25:L25) -> 88.834141

Sheet Quarters
A1: ='Profit & Loss'!A1 -> TRENT LTD | E1: =UPDATE | J1: SCREENER.IN
A3: Narration | B3: ='Data Sheet'!B41 -> 45291 | C3: ='Data Sheet'!C41 -> 45382 | D3: ='Data Sheet'!D41 -> 45473 | E3: ='Data Sheet'!E41 -> 45565 | F3: ='Data Sheet'!F41 -> 45657 | G3: ='Data Sheet'!G41 -> 45747 | H3: ='Data Sheet'!H41 -> 45838 | I3: ='Data Sheet'!I41 -> 45930 | ... K3: ='Data Sheet'!K41 -> 46112
A4: Sales | B4: ='Data Sheet'!B42 -> 3466.62 | C4: ='Data Sheet'!C42 -> 3297.7 | D4: ='Data Sheet'!D42 -> 4104.44 | E4: ='Data Sheet'!E42 -> 4156.67 | F4: ='Data Sheet'!F42 -> 4656.56 | G4: ='Data Sheet'!G42 -> 4216.94 | H4: ='Data Sheet'!H42 -> 4883.48 | I4: ='Data Sheet'!I42 -> 4817.68 | ... K4: ='Data Sheet'!K42 -> 5027.99
A5: Expenses | B5: ='Data Sheet'!B43 -> 2838.1 | C5: ='Data Sheet'!C43 -> 2828.06 | D5: ='Data Sheet'!D43 -> 3491.09 | E5: ='Data Sheet'!E43 -> 3510.95 | F5: ='Data Sheet'!F43 -> 3809.19 | G5: ='Data Sheet'!G43 -> 3566.03 | H5: ='Data Sheet'!H43 -> 4035.62 | I5: ='Data Sheet'!I43 -> 4001.7 | ... K5: ='Data Sheet'!K43 -> 4116.69
A6: Operating Profit | B6: ='Data Sheet'!B50 -> 628.52 | C6: ='Data Sheet'!C50 -> 469.64 | D6: ='Data Sheet'!D50 -> 613.35 | E6: ='Data Sheet'!E50 -> 645.72 | F6: ='Data Sheet'!F50 -> 847.37 | G6: ='Data Sheet'!G50 -> 650.91 | H6: ='Data Sheet'!H50 -> 847.86 | I6: ='Data Sheet'!I50 -> 815.98 | ... K6: ='Data Sheet'!K50 -> 911.3
A7: Other Income | B7: ='Data Sheet'!B44 -> 110.01 | C7: ='Data Sheet'!C44 -> 694.87 | D7: ='Data Sheet'!D44 -> 100.91 | E7: ='Data Sheet'!E44 -> 51.04 | F7: ='Data Sheet'!F44 -> 79.87 | G7: ='Data Sheet'!G44 -> 74.34 | H7: ='Data Sheet'!H44 -> 49.8 | I7: ='Data Sheet'!I44 -> 27.55 | ... K7: ='Data Sheet'!K44 -> 27.91
A8: Depreciation | B8: ='Data Sheet'!B45 -> 164.53 | C8: ='Data Sheet'!C45 -> 212.94 | D8: ='Data Sheet'!D45 -> 181.32 | E8: ='Data Sheet'!E45 -> 196.95 | F8: ='Data Sheet'!F45 -> 244.93 | G8: ='Data Sheet'!G45 -> 271.98 | H8: ='Data Sheet'!H45 -> 292.93 | I8: ='Data Sheet'!I45 -> 324.93 | ... K8: ='Data Sheet'!K45 -> 376.59
A9: Interest | B9: ='Data Sheet'!B46 -> 98.81 | C9: ='Data Sheet'!C46 -> 32.54 | D9: ='Data Sheet'!D46 -> 31.55 | E9: ='Data Sheet'!E46 -> 33 | F9: ='Data Sheet'!F46 -> 36.52 | G9: ='Data Sheet'!G46 -> 37.52 | H9: ='Data Sheet'!H46 -> 40.04 | I9: ='Data Sheet'!I46 -> 41.62 | ... K9: ='Data Sheet'!K46 -> 43.75
A10: Profit before tax | B10: ='Data Sheet'!B47 -> 475.19 | C10: ='Data Sheet'!C47 -> 919.03 | D10: ='Data Sheet'!D47 -> 501.39 | E10: ='Data Sheet'!E47 -> 466.81 | F10: ='Data Sheet'!F47 -> 645.79 | G10: ='Data Sheet'!G47 -> 415.75 | H10: ='Data Sheet'!H47 -> 564.69 | I10: ='Data Sheet'!I47 -> 476.98 | ... K10: ='Data Sheet'!K47 -> 518.87
A11: Tax | B11: ='Data Sheet'!B48 -> 104.55 | C11: ='Data Sheet'!C48 -> 206.94 | D11: ='Data Sheet'!D48 -> 110.18 | E11: ='Data Sheet'!E48 -> 131.75 | F11: ='Data Sheet'!F48 -> 149.25 | G11: ='Data Sheet'!G48 -> 104.15 | H11: ='Data Sheet'!H48 -> 139.99 | I11: ='Data Sheet'!I48 -> 103.56 | ... K11: ='Data Sheet'!K48 -> 105.77
A12: Net profit | B12: ='Data Sheet'!B49 -> 374.36 | C12: ='Data Sheet'!C49 -> 704.23 | D12: ='Data Sheet'!D49 -> 392.57 | E12: ='Data Sheet'!E49 -> 338.75 | F12: ='Data Sheet'!F49 -> 497.25 | G12: ='Data Sheet'!G49 -> 318.15 | H12: ='Data Sheet'!H49 -> 429.69 | I12: ='Data Sheet'!I49 -> 376.86 | ... K12: ='Data Sheet'!K49 -> 400.33
A14: OPM | B14: =IF(B4>0,B6/B4,"") -> 0.18130629 | C14: =IF(C4>0,C6/C4,"") -> 0.14241441 | D14: =IF(D4>0,D6/D4,"") -> 0.14943573 | E14: =IF(E4>0,E6/E4,"") -> 0.1553455 | F14: =IF(F4>0,F6/F4,"") -> 0.18197339 | G14: =IF(G4>0,G6/G4,"") -> 0.154356 | H14: =IF(H4>0,H6/H4,"") -> 0.17361799 | I14: =IF(I4>0,I6/I4,"") -> 0.16937198 | ... K14: =IF(K4>0,K6/K4,"") -> 0.18124539

Sheet Balance Sheet
A1: ='Profit & Loss'!A1 -> TRENT LTD | E1: =UPDATE | J1: SCREENER.IN
A3: Narration | B3: ='Data Sheet'!B56 -> 42825 | C3: ='Data Sheet'!C56 -> 43190 | D3: ='Data Sheet'!D56 -> 43555 | E3: ='Data Sheet'!E56 -> 43921 | F3: ='Data Sheet'!F56 -> 44286 | G3: ='Data Sheet'!G56 -> 44651 | H3: ='Data Sheet'!H56 -> 45016 | I3: ='Data Sheet'!I56 -> 45382 | ... K3: ='Data Sheet'!K56 -> 46112
A4: Equity Share Capital | B4: ='Data Sheet'!B57 -> 33.23 | C4: ='Data Sheet'!C57 -> 33.23 | D4: ='Data Sheet'!D57 -> 33.23 | E4: ='Data Sheet'!E57 -> 35.55 | F4: ='Data Sheet'!F57 -> 35.55 | G4: ='Data Sheet'!G57 -> 35.55 | H4: ='Data Sheet'!H57 -> 35.55 | I4: ='Data Sheet'!I57 -> 35.55 | ... K4: ='Data Sheet'!K57 -> 35.55
A5: Reserves | B5: ='Data Sheet'!B58 -> 1514.46 | C5: ='Data Sheet'!C58 -> 1562.14 | D5: ='Data Sheet'!D58 -> 1613.28 | E5: ='Data Sheet'!E58 -> 2352.22 | F5: ='Data Sheet'!F58 -> 2277.48 | G5: ='Data Sheet'!G58 -> 2328.45 | H5: ='Data Sheet'!H58 -> 2559.94 | I5: ='Data Sheet'!I58 -> 4032.19 | ... K5: ='Data Sheet'!K58 -> 6949.13
A6: Borrowings | B6: ='Data Sheet'!B59 -> 391.74 | C6: ='Data Sheet'!C59 -> 391.43 | D6: ='Data Sheet'!D59 -> 494.14 | E6: ='Data Sheet'!E59 -> 299.74 | F6: ='Data Sheet'!F59 -> 2963.63 | G6: ='Data Sheet'!G59 -> 4725.36 | H6: ='Data Sheet'!H59 -> 4464.14 | I6: ='Data Sheet'!I59 -> 1752.99 | ... K6: ='Data Sheet'!K59 -> 2561.25
A7: Other Liabilities | B7: ='Data Sheet'!B60 -> 282.82 | C7: ='Data Sheet'!C60 -> 349.06 | D7: ='Data Sheet'!D60 -> 418.11 | E7: ='Data Sheet'!E60 -> 2819.17 | F7: ='Data Sheet'!F60 -> 447.07 | G7: ='Data Sheet'!G60 -> 636.66 | H7: ='Data Sheet'!H60 -> 1021.9 | I7: ='Data Sheet'!I60 -> 1341.02 | ... K7: ='Data Sheet'!K60 -> 2182.65
A8: Total | B8: ='Data Sheet'!B61 -> 2222.25 | C8: ='Data Sheet'!C61 -> 2335.86 | D8: ='Data Sheet'!D61 -> 2558.76 | E8: ='Data Sheet'!E61 -> 5506.68 | F8: ='Data Sheet'!F61 -> 5723.73 | G8: ='Data Sheet'!G61 -> 7726.02 | H8: ='Data Sheet'!H61 -> 8081.53 | I8: ='Data Sheet'!I61 -> 7161.75 | ... K8: ='Data Sheet'!K61 -> 11728.58
A10: Net Block | B10: ='Data Sheet'!B62 -> 548.71 | C10: ='Data Sheet'!C62 -> 612.53 | D10: ='Data Sheet'!D62 -> 662.18 | E10: ='Data Sheet'!E62 -> 2738.43 | F10: ='Data Sheet'!F62 -> 3053.82 | G10: ='Data Sheet'!G62 -> 4686.71 | H10: ='Data Sheet'!H62 -> 4526.95 | I10: ='Data Sheet'!I62 -> 2449.92 | ... K10: ='Data Sheet'!K62 -> 5518.74
A11: Capital Work in Progress | B11: ='Data Sheet'!B63 -> 5.48 | C11: ='Data Sheet'!C63 -> 9.59 | D11: ='Data Sheet'!D63 -> 87.18 | E11: ='Data Sheet'!E63 -> 23.32 | F11: ='Data Sheet'!F63 -> 107.98 | G11: ='Data Sheet'!G63 -> 104.72 | H11: ='Data Sheet'!H63 -> 101.72 | I11: ='Data Sheet'!I63 -> 223.78 | ... K11: ='Data Sheet'!K63 -> 253.99
A12: Investments | B12: ='Data Sheet'!B64 -> 1079.96 | C12: ='Data Sheet'!C64 -> 1022.88 | D12: ='Data Sheet'!D64 -> 882.83 | E12: ='Data Sheet'!E64 -> 1514.78 | F12: ='Data Sheet'!F64 -> 1487.29 | G12: ='Data Sheet'!G64 -> 1283.72 | H12: ='Data Sheet'!H64 -> 1109.87 | I12: ='Data Sheet'!I64 -> 1416.03 | ... K12: ='Data Sheet'!K64 -> 1384.91
A13: Other Assets | B13: ='Data Sheet'!B65 -> 588.1 | C13: ='Data Sheet'!C65 -> 690.86 | D13: ='Data Sheet'!D65 -> 926.57 | E13: ='Data Sheet'!E65 -> 1230.15 | F13: ='Data Sheet'!F65 -> 1074.64 | G13: ='Data Sheet'!G65 -> 1650.87 | H13: ='Data Sheet'!H65 -> 2342.99 | I13: ='Data Sheet'!I65 -> 3072.02 | ... K13: ='Data Sheet'!K65 -> 4570.94
A14: Total | B14: ='Data Sheet'!B66 -> 2222.25 | C14: ='Data Sheet'!C66 -> 2335.86 | D14: ='Data Sheet'!D66 -> 2558.76 | E14: ='Data Sheet'!E66 -> 5506.68 | F14: ='Data Sheet'!F66 -> 5723.73 | G14: ='Data Sheet'!G66 -> 7726.02 | H14: ='Data Sheet'!H66 -> 8081.53 | I14: ='Data Sheet'!I66 -> 7161.75 | ... K14: ='Data Sheet'!K66 -> 11728.58
A16: Working Capital | B16: =B13-B7 -> 305.28 | C16: =C13-C7 -> 341.8 | D16: =D13-D7 -> 508.46 | E16: =E13-E7 -> -1589.02 | F16: =F13-F7 -> 627.57 | G16: =G13-G7 -> 1014.21 | H16: =H13-H7 -> 1321.09 | I16: =I13-I7 -> 1731 | ... K16: =K13-K7 -> 2388.29
A17: Debtors | B17: ='Data Sheet'!B67 -> 5.92 | C17: ='Data Sheet'!C67 -> 15.1 | D17: ='Data Sheet'!D67 -> 16.54 | E17: ='Data Sheet'!E67 -> 17.12 | F17: ='Data Sheet'!F67 -> 20.77 | G17: ='Data Sheet'!G67 -> 18.26 | H17: ='Data Sheet'!H67 -> 34.39 | I17: ='Data Sheet'!I67 -> 81.74 | ... K17: ='Data Sheet'!K67 -> 51.14
A18: Inventory | B18: ='Data Sheet'!B68 -> 305.36 | C18: ='Data Sheet'!C68 -> 344.77 | D18: ='Data Sheet'!D68 -> 497.01 | E18: ='Data Sheet'!E68 -> 607.81 | F18: ='Data Sheet'!F68 -> 428.39 | G18: ='Data Sheet'!G68 -> 867.78 | H18: ='Data Sheet'!H68 -> 1361.16 | I18: ='Data Sheet'!I68 -> 1582.73 | ... K18: ='Data Sheet'!K68 -> 2289.01
A20: Debtor Days | B20: =IF('Profit & Loss'!B4>0,'Balance Sheet'!B17/('Profit & Loss'!B4/365),0) -> 1.192205 | C20: =IF('Profit & Loss'!C4>0,'Balance Sheet'!C17/('Profit & Loss'!C4/365),0) -> 2.5546244 | D20: =IF('Profit & Loss'!D4>0,'Balance Sheet'!D17/('Profit & Loss'!D4/365),0) -> 2.2952658 | E20: =IF('Profit & Loss'!E4>0,'Balance Sheet'!E17/('Profit & Loss'!E4/365),0) -> 1.7925519 | F20: =IF('Profit & Loss'!F4>0,'Balance Sheet'!F17/('Profit & Loss'!F4/365),0) -> 2.923705 | G20: =IF('Profit & Loss'!G4>0,'Balance Sheet'!G17/('Profit & Loss'!G4/365),0) -> 1.4817409 | H20: =IF('Profit & Loss'!H4>0,'Balance Sheet'!H17/('Profit & Loss'!H4/365),0) -> 1.5229701 | I20: =IF('Profit & Loss'!I4>0,'Balance Sheet'!I17/('Profit & Loss'!I4/365),0) -> 2.4108957 | ... K20: =IF('Profit & Loss'!K4>0,'Balance Sheet'!K17/('Profit & Loss'!K4/365),0) -> 0.92985477
A21: Inventory Turnover | B21: =IF('Balance Sheet'!B18>0,'Profit & Loss'!B4/'Balance Sheet'!B18,0) -> 5.9354205 | C21: =IF('Balance Sheet'!C18>0,'Profit & Loss'!C4/'Balance Sheet'!C18,0) -> 6.257679 | D21: =IF('Balance Sheet'!D18>0,'Profit & Loss'!D4/'Balance Sheet'!D18,0) -> 5.2921269 | E21: =IF('Balance Sheet'!E18>0,'Profit & Loss'!E4/'Balance Sheet'!E18,0) -> 5.735312 | F21: =IF('Balance Sheet'!F18>0,'Profit & Loss'!F4/'Balance Sheet'!F18,0) -> 6.0528024 | G21: =IF('Balance Sheet'!G18>0,'Profit & Loss'!G4/'Balance Sheet'!G18,0) -> 5.1833644 | H21: =IF('Balance Sheet'!H18>0,'Profit & Loss'!H4/'Balance Sheet'!H18,0) -> 6.0551441 | I21: =IF('Balance Sheet'!I18>0,'Profit & Loss'!I4/'Balance Sheet'!I18,0) -> 7.8188383 | ... K21: =IF('Balance Sheet'!K18>0,'Profit & Loss'!K4/'Balance Sheet'!K18,0) -> 8.7698219
A23: Return on Equity | B23: =IF(SUM('Balance Sheet'!B4:B5)>0,'Profit & Loss'!B12/SUM('Balance Sheet'!B4:B5),"") -> 0.054830102 | C23: =IF(SUM('Balance Sheet'!C4:C5)>0,'Profit & Loss'!C12/SUM('Balance Sheet'!C4:C5),"") -> 0.054514 | D23: =IF(SUM('Balance Sheet'!D4:D5)>0,'Profit & Loss'!D12/SUM('Balance Sheet'!D4:D5),"") -> 0.058888194 | E23: =IF(SUM('Balance Sheet'!E4:E5)>0,'Profit & Loss'!E12/SUM('Balance Sheet'!E4:E5),"") -> 0.051449679 | F23: =IF(SUM('Balance Sheet'!F4:F5)>0,'Profit & Loss'!F12/SUM('Balance Sheet'!F4:F5),"") -> -0.063194165 | G23: =IF(SUM('Balance Sheet'!G4:G5)>0,'Profit & Loss'!G12/SUM('Balance Sheet'!G4:G5),"") -> 0.044767343 | H23: =IF(SUM('Balance Sheet'!H4:H5)>0,'Profit & Loss'!H12/SUM('Balance Sheet'!H4:H5),"") -> 0.17130869 | I23: =IF(SUM('Balance Sheet'!I4:I5)>0,'Profit & Loss'!I12/SUM('Balance Sheet'!I4:I5),"") -> 0.36551009 | ... K23: =IF(SUM('Balance Sheet'!K4:K5)>0,'Profit & Loss'!K12/SUM('Balance Sheet'!K4:K5),"") -> 0.24620312
A24: Return on Capital Emp | C24: =IF((B4+B5+B6+C4+C5+C6)>0,('Profit & Loss'!C10+'Profit & Loss'!C9)*2/(B4+B5+B6+C4+C5+C6),"") -> 0.09700909 | D24: =IF((C4+C5+C6+D4+D5+D6)>0,('Profit & Loss'!D10+'Profit & Loss'!D9)*2/(C4+C5+C6+D4+D5+D6),"") -> 0.10617209 | E24: =IF((D4+D5+D6+E4+E5+E6)>0,('Profit & Loss'!E10+'Profit & Loss'!E9)*2/(D4+D5+D6+E4+E5+E6),"") -> 0.17744234 | F24: =IF((E4+E5+E6+F4+F5+F6)>0,('Profit & Loss'!F10+'Profit & Loss'!F9)*2/(E4+E5+E6+F4+F5+F6),"") -> 0.014055451 | G24: =IF((F4+F5+F6+G4+G5+G6)>0,('Profit & Loss'!G10+'Profit & Loss'!G9)*2/(F4+F5+F6+G4+G5+G6),"") -> 0.070525521 | H24: =IF((G4+G5+G6+H4+H5+H6)>0,('Profit & Loss'!H10+'Profit & Loss'!H9)*2/(G4+G5+G6+H4+H5+H6),"") -> 0.13584857 | I24: =IF((H4+H5+H6+I4+I5+I6)>0,('Profit & Loss'!I10+'Profit & Loss'!I9)*2/(H4+H5+H6+I4+I5+I6),"") -> 0.35534566 | J24: =IF((I4+I5+I6+J4+J5+J6)>0,('Profit & Loss'!J10+'Profit & Loss'!J9)*2/(I4+I5+I6+J4+J5+J6),"") -> 0.32986628 | K24: =IF((J4+J5+J6+K4+K5+K6)>0,('Profit & Loss'!K10+'Profit & Loss'!K9)*2/(J4+J5+J6+K4+K5+K6),"") -> 0.27890397

Sheet Cash Flow
A1: ='Balance Sheet'!A1 -> TRENT LTD | E1: =UPDATE | J1: SCREENER.IN
A3: Narration | B3: ='Data Sheet'!B81 -> 42825 | C3: ='Data Sheet'!C81 -> 43190 | D3: ='Data Sheet'!D81 -> 43555 | E3: ='Data Sheet'!E81 -> 43921 | F3: ='Data Sheet'!F81 -> 44286 | G3: ='Data Sheet'!G81 -> 44651 | H3: ='Data Sheet'!H81 -> 45016 | I3: ='Data Sheet'!I81 -> 45382 | ... K3: ='Data Sheet'!K81 -> 46112
A4: Cash from Operating Activity | B4: ='Data Sheet'!B82 -> 102.44 | C4: ='Data Sheet'!C82 -> 76.86 | D4: ='Data Sheet'!D82 -> 20.98 | E4: ='Data Sheet'!E82 -> 361.16 | F4: ='Data Sheet'!F82 -> 285.03 | G4: ='Data Sheet'!G82 -> 58.08 | H4: ='Data Sheet'!H82 -> 594.88 | I4: ='Data Sheet'!I82 -> 1348.98 | ... K4: ='Data Sheet'!K82 -> 2667.62
A5: Cash from Investing Activity | B5: ='Data Sheet'!B83 -> -43.7 | C5: ='Data Sheet'!C83 -> -4.02 | D5: ='Data Sheet'!D83 -> -37.03 | E5: ='Data Sheet'!E83 -> -808.56 | F5: ='Data Sheet'!F83 -> 17.71 | G5: ='Data Sheet'!G83 -> 56.03 | H5: ='Data Sheet'!H83 -> -102.63 | I5: ='Data Sheet'!I83 -> -508.21 | ... K5: ='Data Sheet'!K83 -> -1578.36
A6: Cash from Financing Activity | B6: ='Data Sheet'!B84 -> -51.36 | C6: ='Data Sheet'!C84 -> -74.31 | D6: ='Data Sheet'!D84 -> 37.47 | E6: ='Data Sheet'!E84 -> 451.94 | F6: ='Data Sheet'!F84 -> -283.11 | G6: ='Data Sheet'!G84 -> -107.98 | H6: ='Data Sheet'!H84 -> -491.41 | I6: ='Data Sheet'!I84 -> -629.45 | ... K6: ='Data Sheet'!K84 -> -1147.61
A7: Net Cash Flow | B7: ='Data Sheet'!B85 -> 7.38 | C7: ='Data Sheet'!C85 -> -1.47 | D7: ='Data Sheet'!D85 -> 21.42 | E7: ='Data Sheet'!E85 -> 4.54 | F7: ='Data Sheet'!F85 -> 19.63 | G7: ='Data Sheet'!G85 -> 6.13 | H7: ='Data Sheet'!H85 -> 0.84 | I7: ='Data Sheet'!I85 -> 211.32 | ... K7: ='Data Sheet'!K85 -> -58.35

Sheet Customization
A1: How to use it?
A3: You can customize this workbook as you want.
B4: You can add custom formating, add conditional formating, add your own formulas… do ANYTHING.
B5: Please don't edit the "Data Sheet" only.
A7: After customization, you can upload this back on Screener.
B8: Upload on: | C8: https://www.screener.in/excel/
A10: Download your customized workbooks now onwards.
B11: Now whenever you will "Export to excel" from Screener, it will export your customized file.
A14: TESTING:
B15: This is a testing feature currently.
B16: You can report any formula errors on the worksheet at: support@screener.in

Sheet Data Sheet
A1: COMPANY NAME | B1: TRENT LTD | E1: =IF(B2<>B3, "A NEW VERSION OF THE WORKSHEET IS AVAILABLE", "")
A2: LATEST VERSION | B2: 2.1 | E2: PLEASE DO NOT MAKE ANY CHANGES TO THIS SHEET
A3: CURRENT VERSION | B3: 2.1
A5: META
A6: Number of shares | B6: =IF(B9>0, B9/B8, 0) -> 35.548747
A7: Face Value | B7: 1
A8: Current Price | B8: 4297.3
A9: Market Capitalization | B9: 152763.63
A15: PROFIT & LOSS
A16: Report Date | B16: 42825 | C16: 43190 | D16: 43555 | E16: 43921 | F16: 44286 | G16: 44651 | H16: 45016 | I16: 45382 | J16: 45747 | K16: 46112
A17: Sales | B17: 1812.44 | C17: 2157.46 | D17: 2630.24 | E17: 3485.98 | F17: 2592.96 | G17: 4498.02 | H17: 8242.02 | I17: 12375.11 | J17: 17134.61 | K17: 20074.21
A18: Raw Material Cost | B18: 911.22 | C18: 1070.02 | D18: 1459.67 | E18: 1951.64 | F18: 1371.64 | G18: 2920.38 | H18: 5211.05 | I18: 7123.6 | J18: 10143.39 | K18: 11496.89
A19: Change in Inventory | B19: 29.86 | C19: 38.51 | D19: 148.23 | E19: 69.89 | F19: -162.36 | G19: 438.84 | H19: 491.31 | I19: 164.71 | J19: 454.25 | K19: 232.18
A20: Power and Fuel | B20: 51.28 | C20: 52.75 | D20: 59.18 | E20: 66.64 | F20: 49.41 | G20: 71.89 | H20: 144.28 | I20: 229.16 | J20: 349.87
A21: Other Mfr. Exp | B21: 81.91 | C21: 90.78 | D21: 122.09 | E21: 97.51 | F21: 92 | G21: 127.14 | H21: 211.99 | I21: 264.59 | J21: 369.79
A22: Employee Cost | B22: 194.72 | C22: 233.02 | D22: 288.89 | E22: 361.01 | F22: 303.4 | G22: 402.92 | H22: 659.07 | I22: 1041.74 | J22: 1315.54 | K22: 1355.49
A23: Selling and admin | B23: 407.07 | C23: 450.61 | D23: 514.41 | E23: 436.82 | F23: 364.62 | G23: 705.03 | H23: 1252.53 | I23: 1709.55 | J23: 2322.83 | K23: 1563.94
A24: Other Expenses | B24: 62.57 | C24: 90.29 | D24: 93.59 | E24: 113.28 | F24: 135.66 | G24: 114.78 | H24: 140.26 | I24: 200.49 | J24: 267.48 | K24: 2216.68
A25: Other Income | B25: 81.31 | C25: 27.47 | D25: 30.14 | E25: 146.63 | F25: 199.4 | G25: 152.16 | H25: 340.6 | I25: 988.91 | J25: 305.06 | K25: 92.63
A26: Depreciation | B26: 41.29 | C26: 45.53 | D26: 51.67 | E26: 247.24 | F26: 257.3 | G26: 310.82 | H26: 493.69 | I26: 671.11 | J26: 895.18 | K26: 1361.19
A27: Interest | B27: 45.55 | C27: 43.78 | D27: 50.64 | E27: 263.37 | F27: 260.79 | G27: 324.84 | H27: 408.99 | I27: 367.66 | J27: 200.1 | K27: 168.35
A28: Profit before tax | B28: 128 | C28: 146.66 | D28: 168.47 | E28: 164.99 | F28: -204.82 | G28: 111.22 | H28: 552.07 | I28: 1920.83 | J28: 2029.74 | K28: 2236.48
A29: Tax | B29: 43.05 | C29: 59.62 | D29: 73.61 | E29: 59.01 | F29: -23.69 | G29: 76.62 | H29: 158.44 | I29: 443.37 | J29: 495.33 | K29: 515.15
A30: Net profit | B30: 84.86 | C30: 86.97 | D30: 96.96 | E30: 122.85 | F30: -146.17 | G30: 105.83 | H30: 444.63 | I30: 1486.8 | J30: 1546.72 | K30: 1719.65
A31: Dividend Amount | B31: 33.23 | C31: 38.21 | D31: 43.2 | E31: 35.55 | F31: 21.33 | G31: 60.44 | H31: 78.21 | I31: 113.76 | J31: 177.75 | K31: 213.3
A40: Quarters
A41: Report Date | B41: 45291 | C41: 45382 | D41: 45473 | E41: 45565 | F41: 45657 | G41: 45747 | H41: 45838 | I41: 45930 | J41: 46022 | K41: 46112
A42: Sales | B42: 3466.62 | C42: 3297.7 | D42: 4104.44 | E42: 4156.67 | F42: 4656.56 | G42: 4216.94 | H42: 4883.48 | I42: 4817.68 | J42: 5345.06 | K42: 5027.99
A43: Expenses | B43: 2838.1 | C43: 2828.06 | D43: 3491.09 | E43: 3510.95 | F43: 3809.19 | G43: 3566.03 | H43: 4035.62 | I43: 4001.7 | J43: 4263.99 | K43: 4116.69
A44: Other Income | B44: 110.01 | C44: 694.87 | D44: 100.91 | E44: 51.04 | F44: 79.87 | G44: 74.34 | H44: 49.8 | I44: 27.55 | J44: 4.55 | K44: 27.91
A45: Depreciation | B45: 164.53 | C45: 212.94 | D45: 181.32 | E45: 196.95 | F45: 244.93 | G45: 271.98 | H45: 292.93 | I45: 324.93 | J45: 366.74 | K45: 376.59
A46: Interest | B46: 98.81 | C46: 32.54 | D46: 31.55 | E46: 33 | F46: 36.52 | G46: 37.52 | H46: 40.04 | I46: 41.62 | J46: 42.94 | K46: 43.75
A47: Profit before tax | B47: 475.19 | C47: 919.03 | D47: 501.39 | E47: 466.81 | F47: 645.79 | G47: 415.75 | H47: 564.69 | I47: 476.98 | J47: 675.94 | K47: 518.87
A48: Tax | B48: 104.55 | C48: 206.94 | D48: 110.18 | E48: 131.75 | F48: 149.25 | G48: 104.15 | H48: 139.99 | I48: 103.56 | J48: 165.83 | K48: 105.77
A49: Net profit | B49: 374.36 | C49: 704.23 | D49: 392.57 | E49: 338.75 | F49: 497.25 | G49: 318.15 | H49: 429.69 | I49: 376.86 | J49: 512.77 | K49: 400.33
A50: Operating Profit | B50: 628.52 | C50: 469.64 | D50: 613.35 | E50: 645.72 | F50: 847.37 | G50: 650.91 | H50: 847.86 | I50: 815.98 | J50: 1081.07 | K50: 911.3
A55: BALANCE SHEET
A56: Report Date | B56: 42825 | C56: 43190 | D56: 43555 | E56: 43921 | F56: 44286 | G56: 44651 | H56: 45016 | I56: 45382 | J56: 45747 | K56: 46112
A57: Equity Share Capital | B57: 33.23 | C57: 33.23 | D57: 33.23 | E57: 35.55 | F57: 35.55 | G57: 35.55 | H57: 35.55 | I57: 35.55 | J57: 35.55 | K57: 35.55
A58: Reserves | B58: 1514.46 | C58: 1562.14 | D58: 1613.28 | E58: 2352.22 | F58: 2277.48 | G58: 2328.45 | H58: 2559.94 | I58: 4032.19 | J58: 5426.19 | K58: 6949.13
...

Sheet Balance sheet row data
B4: Particular | C4: 44256 | D4: 44621 | E4: 44986 | F4: 45352 | G4: 45717
B5: Equity Capital | C5: 36 | D5: 36 | E5: 36 | F5: 36 | G5: 36
B6: Reserves | C6: 2277 | D6: 2328 | E6: 2560 | F6: 4032 | G6: 5426
B7: Borrowings -
B8: Long term Borrowings | C8: 0 | D8: 497 | E8: 498 | F8: 499 | G8: 499
B9: Short term Borrowings | C9: 300 | D9: 0 | E9: 0 | F9: 0 | G9: 0
B10: Lease Liabilities | C10: 2664 | D10: 4228 | E10: 3966 | F10: 1254 | G10: 1738
B11: Non controlling int | C11: 44 | D11: 46 | E11: 67 | F11: 35 | G11: 122
B12: Trade Payables | C12: 275 | D12: 378 | E12: 665 | F12: 774 | G12: 928
B13: Other liability items | C13: 128 | D13: 213 | E13: 289 | F13: 532 | G13: 671
B14: Total Liabilities | C14: 5724 | D14: 7726 | E14: 8082 | F14: 7162 | G14: 9420
B16: Fixed Assets -
B17: Land | C17: 63 | D17: 62 | E17: 77 | F17: 86 | G17: 86
B18: Building | C18: 3117 | D18: 4893 | E18: 4855 | F18: 2162 | G18: 3664
B19: Plant Machinery | C19: 168 | D19: 221 | E19: 287 | F19: 437 | G19: 825
B20: Equipments | C20: 30 | D20: 33 | E20: 39 | F20: 44 | G20: 56
B21: Computers | C21: 59 | D21: 70 | E21: 98 | F21: 112 | G21: 175
B22: Furniture n fittings | C22: 192 | D22: 225 | E22: 328 | F22: 486 | G22: 758
B23: Vehicles | C23: 3 | D23: 3 | E23: 3 | F23: 3 | G23: 4
B24: Intangible Assets | C24: 62 | D24: 62 | E24: 62 | F24: 62 | G24: 62
B25: Other fixed assets | C25: 70 | D25: 78 | E25: 92 | F25: 92 | G25: 98
B26: Gross Block | C26: 3765 | D26: 5647 | E26: 5840 | F26: 3485 | G26: 5730
B27: Accumulated Depreciation | C27: 711 | D27: 961 | E27: 1314 | F27: 1035 | G27: 1835
B29: Non- Current Assets | C29: =C26-C27 -> 3054 | D29: =D26-D27 -> 4686 | E29: =E26-E27 -> 4526 | F29: =F26-F27 -> 2450 | G29: =G26-G27 -> 3895
B31: CWIP | C31: 108 | D31: 105 | E31: 102 | F31: 224 | G31: 180
B32: Investments | C32: 1487 | D32: 1284 | E32: 1110 | F32: 1416 | G32: 1480
B34: Current Assets
B35: Inventories | C35: 428 | D35: 868 | E35: 1361 | F35: 1583 | G35: 2045
B36: Trade receivables | C36: 21 | D36: 18 | E36: 34 | F36: 82 | G36: 63
B37: Cash Equivalents | C37: 81 | D37: 86 | E37: 86 | F37: 298 | G37: 340
B38: Loans n Advances | C38: 28 | D38: 29 | E38: 29 | F38: 35 | G38: 17
B39: Other asset items | C39: 516 | D39: 650 | E39: 832 | F39: 1075 | G39: 1400
B40: Total Current Assets | C40: =SUM(C35:C39) -> 1074 | D40: =SUM(D35:D39) -> 1651 | E40: =SUM(E35:E39) -> 2342 | F40: =SUM(F35:F39) -> 3073 | G40: =SUM(G35:G39) -> 3865
B42: Total Assets | C42: 5724 | D42: 7726 | E42: 8082 | F42: 7162 | G42: 9420

Sheet Forcasting of Sales
B2: Key Assumption & Methodology
B4: Parameter | D4: Value | F4: Retionale
B5: Valuation Date
B6: Projection Period
B7: Revenue Growth % | D7: 0.25 | F7: Based on Management Guidence
B8: Annual Growth Tapering | D8: 0.02
B9: Terminal Growth Rate | D9: 0.05
B10: Risk-Free Rate (Rf) | D10: 6.5 | F10: 10 years Gov bond Rate
B11: Equity Risk Premium (ERP) | D11: =WACC!J22-WACC!J21 -> 0.085 | F11: Index Avg Return - Bond Rate
B12: Tax Rate | D12: 0.25
B14: ="Revenue Projection & Growth Assumption "&" - "&'Data Sheet'!B1 -> Revenue Projection & Growth Assumption - TRENT LTD
B16: Year | D16: ='Historical Data'!H3+365 -> 46112 | E16: =D16+365 -> 46477 | F16: =E16+365 -> 46842 | G16: =F16+365 -> 47207 | H16: =G16+365 -> 47572
B17: Revenue Grwoth % | D17: {=CHOOSE(E20,D21:H21,D22:H22,D23:H23)} -> 0.25 | E17: 0.23 | F17: 0.21 | G17: 0.19 | H17: 0.17
B18: Revenue (INR) | D18: ='Historical Data'!H7*(1+'Forcasting of Sales'!D17) -> 21418.263 | E18: =D18*(1+E17) -> 26344.463 | F18: =E18*(1+F17) -> 31876.8 | G18: =F18*(1+G17) -> 37933.392 | H18: =G18*(1+H17) -> 44382.069
B20: Chosen Scenario: | D20: Base Case | E20: =MATCH(D20,B21:B23,0) -> 1
B21: Base Case | D21: =D7 -> 0.25 | E21: =D21-$D$8 -> 0.23 | F21: =E21-$D$8 -> 0.21 | G21: =F21-$D$8 -> 0.19 | H21: =G21-$D$8 -> 0.17
B22: Best Case | D22: =D21+5% -> 0.3 | E22: =D22-$D$8 -> 0.28 | F22: =E22-$D$8 -> 0.26 | G22: =F22-$D$8 -> 0.24 | H22: =G22-$D$8 -> 0.22
B23: Worst Case | D23: =D21-5% -> 0.2 | E23: =D23-$D$8 -> 0.18 | F23: =E23-$D$8 -> 0.16 | G23: =F23-$D$8 -> 0.14 | H23: =G23-$D$8 -> 0.12

Sheet Cashflow Row data
C3: 44256 | D3: 44621 | E3: 44986 | F3: 45352 | G3: 45717
B4: Cash from Operating Activity - | C4: 285 | D4: 58 | E4: 595 | F4: 1349 | G4: 1661
B5: Profit from operations | C5: 180 | D5: 569 | E5: 1079 | F5: 1919 | G5: 2723
B6: Receivables | C6: -39 | D6: -103 | E6: -101 | F6: -208 | G6: -203
B7: Inventory | C7: 179 | D7: -439 | E7: -494 | F7: -222 | G7: -462
B8: Payables | C8: -11 | D8: 134 | E8: 332 | F8: 178 | G8: 212
B9: Loans Advances | C9: 0 | D9: 0 | E9: 0 | F9: 0 | G9: 0
B10: Other WC items | C10: -23 | D10: -22 | E10: -30 | F10: -20 | G10: -115
B11: Working capital changes | C11: 106 | D11: -430 | E11: -293 | F11: -272 | G11: -568
B12: Interest paid | C12: 0 | D12: 0 | E12: 0 | F12: 0 | G12: 0
B13: Direct taxes | C13: -1 | D13: -82 | E13: -191 | F13: -299 | G13: -494
B14: Cash from Investing Activity - | C14: 18 | D14: 56 | E14: -103 | F14: -508 | G14: -923
B15: Fixed assets purchased | C15: -113 | D15: -271 | E15: -503 | F15: -737 | G15: -1268
... B35: Net Cash Flow | C35: 20 | D35: 6 | E35: 1 | F35: 211 | G35: 44

Sheet Historical Data
B1: ="Historical Financial Statement - "&'Data Sheet'!B1 -> Historical Financial Statement - TRENT LTD
B3: Year | D3: ='Data Sheet'!F56 -> 44286 | E3: ='Data Sheet'!G56 -> 44651 | F3: ='Data Sheet'!H56 -> 45016 | G3: ='Data Sheet'!I56 -> 45382 | H3: ='Data Sheet'!J56 -> 45747
A5: # | B5: ="Income Statement "& " - "&'Data Sheet'!B1 -> Income Statement - TRENT LTD
B7: Sales | D7: =IFERROR('Data Sheet'!F17,0) -> 2592.96 | E7: =IFERROR('Data Sheet'!G17,0) -> 4498.02 | F7: =IFERROR('Data Sheet'!H17,0) -> 8242.02 | G7: =IFERROR('Data Sheet'!I17,0) -> 12375.11 | H7: =IFERROR('Data Sheet'!J17,0) -> 17134.61
B8: Sales Growth | E8: =E7/D7-1 -> 0.73470474 | F8: =F7/E7-1 -> 0.83236624 | G8: =G7/F7-1 -> 0.50146566 | H8: =H7/G7-1 -> 0.38460264
B9: COGS | D9: =IFERROR(SUM('Data Sheet'!F18,-'Data Sheet'!F19,'Data Sheet'!F20,'Data Sheet'!F21),0) -> 1675.41 | E9: =IFERROR(SUM('Data Sheet'!G18,-'Data Sheet'!G19,'Data Sheet'!G20,'Data Sheet'!G21),0) -> 2680.57 | F9: =IFERROR(SUM('Data Sheet'!H18,-'Data Sheet'!H19,'Data Sheet'!H20,'Data Sheet'!H21),0) -> 5076.01 | G9: =IFERROR(SUM('Data Sheet'!I18,-'Data Sheet'!I19,'Data Sheet'!I20,'Data Sheet'!I21),0) -> 7452.64 | H9: =IFERROR(SUM('Data Sheet'!J18,-'Data Sheet'!J19,'Data Sheet'!J20,'Data Sheet'!J21),0) -> 10408.8
B10: COGS %of Sales | D10: =D9/D7 -> 0.646138 | E10: =E9/E7 -> 0.59594444 | F10: =F9/F7 -> 0.61586965 | G10: =G9/G7 -> 0.60222818 | H10: =H9/H7 -> 0.60747224
B11: Gross Profit | D11: =D7-D9 -> 917.55 | E11: =E7-E9 -> 1817.45 | F11: =F7-F9 -> 3166.01 | G11: =G7-G9 -> 4922.47 | H11: =H7-H9 -> 6725.81
B12: Gross Margin | D12: =D11/D7 -> 0.353862 | E12: =E11/E7 -> 0.40405556 | F12: =F11/F7 -> 0.38413035 | G12: =G11/G7 -> 0.39777182 | H12: =H11/H7 -> 0.39252776
B13: Selling & General Expenses | D13: =IFERROR(SUM('Data Sheet'!F22:F24),0) -> 803.68 | E13: =IFERROR(SUM('Data Sheet'!G22:G24),0) -> 1222.73 | F13: =IFERROR(SUM('Data Sheet'!H22:H24),0) -> 2051.86 | G13: =IFERROR(SUM('Data Sheet'!I22:I24),0) -> 2951.78 | H13: =IFERROR(SUM('Data Sheet'!J22:J24),0) -> 3905.85
B14: SG&A as % of sales | D14: =D13/D7 -> 0.30994693 | E14: =E13/E7 -> 0.27183739 | F14: =F13/F7 -> 0.24895111 | G14: =G13/G7 -> 0.23852556 | H14: =H13/H7 -> 0.22795091
B15: EBIDTA | D15: =D11-D13 -> 113.87 | E15: =E11-E13 -> 594.72 | F15: =F11-F13 -> 1114.15 | G15: =G11-G13 -> 1970.69 | H15: =H11-H13 -> 2819.96
B16: EBIDTA Margin | D16: =D15/D7 -> 0.043915062 | E16: =E15/E7 -> 0.13221818 | F16: =F15/F7 -> 0.13517924 | G16: =G15/G7 -> 0.15924626 | H16: =H15/H7 -> 0.16457684
B17: Depreciation | D17: =IFERROR('Data Sheet'!F26,0) -> 257.3 | E17: =IFERROR('Data Sheet'!G26,0) -> 310.82 | F17: =IFERROR('Data Sheet'!H26,0) -> 493.69 | G17: =IFERROR('Data Sheet'!I26,0) -> 671.11 | H17: =IFERROR('Data Sheet'!J26,0) -> 895.18
B18: Depreciation%of Net block | D18: =IFERROR('Data Sheet'!F26/'Data Sheet'!F62,0) -> 0.08425513 | E18: =IFERROR('Data Sheet'!G26/'Data Sheet'!G62,0) -> 0.066319444 | F18: =IFERROR('Data Sheet'!H26/'Data Sheet'!H62,0) -> 0.10905577 | G18: =IFERROR('Data Sheet'!I26/'Data Sheet'!I62,0) -> 0.27393139 | H18: =IFERROR('Data Sheet'!J26/'Data Sheet'!J62,0) -> 0.22982031
B19: EBIT | D19: =D15-D17 -> -143.43 | E19: =E15-E17 -> 283.9 | F19: =F15-F17 -> 620.46 | G19: =G15-G17 -> 1299.58 | H19: =H15-H17 -> 1924.78
B20: EBIT as % of sales | D20: =D19/D7 -> -0.055315161 | E20: =E19/E7 -> 0.06311666 | F20: =F19/F7 -> 0.075280089 | G20: =G19/G7 -> 0.10501563 | H20: =H19/H7 -> 0.11233287
B21: Other Income | D21: =IFERROR('Data Sheet'!F25,0) -> 199.4 | E21: =IFERROR('Data Sheet'!G25,0) -> 152.16 | F21: =IFERROR('Data Sheet'!H25,0) -> 340.6 | G21: =IFERROR('Data Sheet'!I25,0) -> 988.91 | H21: =IFERROR('Data Sheet'!J25,0) -> 305.06
B22: Intreste | D22: =IFERROR('Data Sheet'!F27,0) -> 260.79 | E22: =IFERROR('Data Sheet'!G27,0) -> 324.84 | F22: =IFERROR('Data Sheet'!H27,0) -> 408.99 | G22: =IFERROR('Data Sheet'!I27,0) -> 367.66 | H22: =IFERROR('Data Sheet'!J27,0) -> 200.1
B23: Intreste%of Debt | D23: =IFERROR(D22/'Data Sheet'!F59,0) -> 0.087996815 | E23: =IFERROR(E22/'Data Sheet'!G59,0) -> 0.068743969 | F23: =IFERROR(F22/'Data Sheet'!H59,0) -> 0.09161675 | G23: =IFERROR(G22/'Data Sheet'!I59,0) -> 0.20973308 | H23: =IFERROR(H22/'Data Sheet'!J59,0) -> 0.08944256
B24: Earing Before Tax | D24: =D19+D21-D22 -> -204.82 | E24: =E19+E21-E22 -> 111.22 | F24: =F19+F21-F22 -> 552.07 | G24: =G19+G21-G22 -> 1920.83 | H24: =H19+H21-H22 -> 2029.74
B25: EBT % of sales | D25: =D24/D7 -> -0.078990806 | E25: =E24/E7 -> 0.024726435 | F25: =F24/F7 -> 0.066982366 | G25: =G24/G7 -> 0.15521721 | H25: =H24/H7 -> 0.11845849
B26: Tax | D26: =IFERROR('Data Sheet'!F29,0) -> -23.69 | E26: =IFERROR('Data Sheet'!G29,0) -> 76.62 | F26: =IFERROR('Data Sheet'!H29,0) -> 158.44 | G26: =IFERROR('Data Sheet'!I29,0) -> 443.37 | H26: =IFERROR('Data Sheet'!J29,0) -> 495.33
B27: Effective Tax Rate | D27: =D26/D24 -> 0.11566253 | E27: =E26/E24 -> 0.68890487 | F27: =F26/F24 -> 0.28699259 | G27: =G26/G24 -> 0.23082209 | H27: =H26/H24 -> 0.24403618
B28: Net Profit (PAT) | D28: =D24-D26 -> -181.13 | E28: =E24-E26 -> 34.6 | F28: =F24-F26 -> 393.63 | G28: =G24-G26 -> 1477.46 | H28: =H24-H26 -> 1534.41
B29: Net Profit %of Sales | D29: =D28/D7 -> -0.069854529 | E29: =E28/E7 -> 0.0076922735 | F29: =F28/F7 -> 0.047758923 | G29: =G28/G7 -> 0.11938965 | H29: =H28/H7 -> 0.089550331
A32: # | B32: ="BalanceSheet "& " - "&'Data Sheet'!B1 -> BalanceSheet - TRENT LTD
B33: Equity Share Capital | D33: =IFERROR('Data Sheet'!F57,0) -> 35.55 | E33: =IFERROR('Data Sheet'!G57,0) -> 35.55 | F33: =IFERROR('Data Sheet'!H57,0) -> 35.55 | G33: =IFERROR('Data Sheet'!I57,0) -> 35.55 | H33: =IFERROR('Data Sheet'!J57,0) -> 35.55
B34: Reserves | D34: =IFERROR('Data Sheet'!F58,0) -> 2277.48 | E34: =IFERROR('Data Sheet'!G58,0) -> 2328.45 | F34: =IFERROR('Data Sheet'!H58,0) -> 2559.94 | G34: =IFERROR('Data Sheet'!I58,0) -> 4032.19 | H34: =IFERROR('Data Sheet'!J58,0) -> 5426.19
B35: Borrowings | D35: =IFERROR('Data Sheet'!F59,0) -> 2963.63 | E35: =IFERROR('Data Sheet'!G59,0) -> 4725.36 | F35: =IFERROR('Data Sheet'!H59,0) -> 4464.14 | G35: =IFERROR('Data Sheet'!I59,0) -> 1752.99 | H35: =IFERROR('Data Sheet'!J59,0) -> 2237.19
B36: Other Liabilities | D36: =IFERROR('Data Sheet'!F60,0) -> 447.07 | E36: =IFERROR('Data Sheet'!G60,0) -> 636.66 | F36: =IFERROR('Data Sheet'!H60,0) -> 1021.9 | G36: =IFERROR('Data Sheet'!I60,0) -> 1341.02 | H36: =IFERROR('Data Sheet'!J60,0) -> 1720.71
B37: Total Liablities | D37: =SUM(D33:D36) -> 5723.73 | E37: =SUM(E33:E36) -> 7726.02 | F37: =SUM(F33:F36) -> 8081.53 | G37: =SUM(G33:G36) -> 7161.75 | H37: =SUM(H33:H36) -> 9419.64
B39: Net Block | D39: =IFERROR('Data Sheet'!F62,0) -> 3053.82 | E39: =IFERROR('Data Sheet'!G62,0) -> 4686.71 | F39: =IFERROR('Data Sheet'!H62,0) -> 4526.95 | G39: =IFERROR('Data Sheet'!I62,0) -> 2449.92 | H39: =IFERROR('Data Sheet'!J62,0) -> 3895.13
B40: Capital Work in Progress | D40: =IFERROR('Data Sheet'!F63,0) -> 107.98 | E40: =IFERROR('Data Sheet'!G63,0) -> 104.72 | F40: =IFERROR('Data Sheet'!H63,0) -> 101.72 | G40: =IFERROR('Data Sheet'!I63,0) -> 223.78 | H40: =IFERROR('Data Sheet'!J63,0) -> 179.5
B41: Investments | D41: =IFERROR('Data Sheet'!F64,0) -> 1487.29 | E41: =IFERROR('Data Sheet'!G64,0) -> 1283.72 | F41: =IFERROR('Data Sheet'!H64,0) -> 1109.87 | G41: =IFERROR('Data Sheet'!I64,0) -> 1416.03 | H41: =IFERROR('Data Sheet'!J64,0) -> 1480.25
B42: Other Assets | D42: =IFERROR(('Data Sheet'!F65-SUM('Data Sheet'!F67:F69)),0) -> 544.01 | E42: =IFERROR(('Data Sheet'!G65-SUM('Data Sheet'!G67:G69)),0) -> 678.86 | F42: =IFERROR(('Data Sheet'!H65-SUM('Data Sheet'!H67:H69)),0) -> 861.14 | G42: =IFERROR(('Data Sheet'!I65-SUM('Data Sheet'!I67:I69)),0) -> 1109.99 | H42: =IFERROR(('Data Sheet'!J65-SUM('Data Sheet'!J67:J69)),0) -> 1416.92
B43: Non- Current Assets | D43: =SUM(D39:D42) -> 5193.1 | E43: =SUM(E39:E42) -> 6754.01 | F43: =SUM(F39:F42) -> 6599.68 | G43: =SUM(G39:G42) -> 5199.72 | H43: =SUM(H39:H42) -> 6971.8
B44: Receivables | D44: =IFERROR('Data Sheet'!F67,0) -> 20.77 | E44: =IFERROR('Data Sheet'!G67,0) -> 18.26 | F44: =IFERROR('Data Sheet'!H67,0) -> 34.39 | G44: =IFERROR('Data Sheet'!I67,0) -> 81.74 | H44: =IFERROR('Data Sheet'!J67,0) -> 62.95
B45: Inventory | D45: =IFERROR('Data Sheet'!F68,0) -> 428.39 | E45: =IFERROR('Data Sheet'!G68,0) -> 867.78 | F45: =IFERROR('Data Sheet'!H68,0) -> 1361.16 | G45: =IFERROR('Data Sheet'!I68,0) -> 1582.73 | H45: =IFERROR('Data Sheet'!J68,0) -> 2045.05
B46: Cash & Bank | D46: =IFERROR('Data Sheet'!F69,0) -> 81.47 | E46: =IFERROR('Data Sheet'!G69,0) -> 85.97 | F46: =IFERROR('Data Sheet'!H69,0) -> 86.3 | G46: =IFERROR('Data Sheet'!I69,0) -> 297.56 | H46: =IFERROR('Data Sheet'!J69,0) -> 339.84
...

Sheet WACC
B1: Weighted Average Cost of Capital
B3: Peer Comparable WACC
G5: Debt/ | H5: Debt/ | I5: Levered | J5: Unlevered
B6: Peer Coms | C6: Country | D6: Market cap | E6: Debt | F6: Tax | G6: Equity | H6: Capital | I6: Beta 2 | J6: Beta 3
B7: Trent | C7: India | D7: 152763.63 | E7: 2561.25 | F7: 0.25 | G7: =E7/D7 -> 0.016766098 | H7: =E7/(D7+E7) -> 0.016489631 | I7: 1.6 | J7: =I7/(1+(1-F7)*G7) -> 1.5801305
B8: Lenskart Solut. | C8: India | D8: 92698.57 | E8: 2857.8 | F8: 0.25 | G8: =E8/D8 -> 0.030828955 | H8: =E8/(D8+E8) -> 0.029906954 | I8: 0.25 | J8: =I8/(1+(1-F8)*G8) -> 0.2443502
B9: A B Lifestyle | C9: India | D9: 12835.01 | E9: 3496.03 | F9: 0.25 | G9: =E9/D9 -> 0.27238234 | H9: =E9/(D9+E9) -> 0.21407271 | I9: 0.88 | J9: =I9/(1+(1-F9)*G9) -> 0.73072298
B10: Vedant Fashions | C10: India | D10: 10935 | E10: 463.76 | F10: 0.25 | G10: =E10/D10 -> 0.042410608 | H10: =E10/(D10+E10) -> 0.040685127 | I10: 1.28 | J10: =I10/(1+(1-F10)*G10) -> 1.2405409
E12: Average | F12: =AVERAGE(F7:F10) -> 0.25 | G12: =AVERAGE(G7:G10) -> 0.090596999 | H12: =AVERAGE(H7:H10) -> 0.075288606 | I12: =AVERAGE(I7:I10) -> 1.0025 | J12: =AVERAGE(J7:J10) -> 0.94893616
E13: Median | F13: =MEDIAN(F7:F10) -> 0.25 | G13: =MEDIAN(G7:G10) -> 0.036619781 | H13: =MEDIAN(H7:H10) -> 0.035296041 | I13: =MEDIAN(I7:I10) -> 1.08 | J13: =MEDIAN(J7:J10) -> 0.98563195
B19: Cost of Debt | G19: Cost of Debt
B21: Pre-Tax Cost of Debt | D21: 0.078094494 | G21: Risk Free Return | J21: 0.065
B22: Tax rate | D22: =F7 -> 0.25 | G22: Market Return | J22: 0.15
B23: Post Tax Cost of Debt | D23: =D21*(1-D22) -> 0.058570871 | G23: Levered Beta 2 | J23: =J34 -> 1.0458185
G24: Cost of Equity | J24: =J21+(J22-J21)*J23 -> 0.15389457
B29: Capital Structure | G29: Levered Beta
D30: Current | E30: Target
B31: Debt | C31: =E7 -> 2561.25 | D31: =C31/C33 -> 0.016489631 | E31: =H12 -> 0.075288606 | G31: Unlevered Beta | J31: =J13 -> 0.98563195
B32: Market Cap | C32: =D7 -> 152763.63 | D32: =C32/C33 -> 0.98351037 | E32: =E33-E31 -> 0.92471139 | G32: Tax rate | J32: =D22 -> 0.25
B33: Total Capital | C33: =SUM(C31:C32) -> 155324.88 | D33: =SUM(D31:D32) -> 1 | E33: =D33 -> 1 | G33: Targeted Debt/Equity | J33: =E37 -> 0.081418491
G34: Levered Beta | J34: =J31*(1+(1-J32)*J33) -> 1.0458185
D36: Current | E36: Target
B37: Debt/Equity | D37: =D31/D32 -> 0.016766098 | E37: =E31/E32 -> 0.081418491
G38: Weighted Average Cost of Capital
G40: Post Tax Cost of Debt (Kd) | J40: =D23 -> 0.058570871
G41: Targeted Weighted Debt | J41: =E31 -> 0.075288606
G43: Cost of Equity (Ke) | J43: =J24 -> 0.15389457
G44: Targeted Weighted Equity | J44: =E32 -> 0.92471139
G45: WACC | J45: =(J40*J41)+(J43*J44) -> 0.14671778

Sheet Intresic Growth
B3: Intrinsic Growth Rate Calculation
B6: Particulars | D6: ='Historical Data'!D3 -> 44286 | E6: ='Historical Data'!E3 -> 44651 | F6: ='Historical Data'!F3 -> 45016 | G6: ='Historical Data'!G3 -> 45382 | H6: ='Historical Data'!H3 -> 45747
B8: Calculation of ROIC
B9: Current Assets
B10: Inventories | D10: =IFERROR('Balance sheet row data'!C35,0) -> 428 | E10: =IFERROR('Balance sheet row data'!D35,0) -> 868 | F10: =IFERROR('Balance sheet row data'!E35,0) -> 1361 | G10: =IFERROR('Balance sheet row data'!F35,0) -> 1583 | H10: =IFERROR('Balance sheet row data'!G35,0) -> 2045
B11: Trade receivables | D11: =IFERROR('Balance sheet row data'!C36,0) -> 21 | E11: =IFERROR('Balance sheet row data'!D36,0) -> 18 | F11: =IFERROR('Balance sheet row data'!E36,0) -> 34 | G11: =IFERROR('Balance sheet row data'!F36,0) -> 82 | H11: =IFERROR('Balance sheet row data'!G36,0) -> 63
B12: Other asset items | D12: =IFERROR('Balance sheet row data'!C39,0) -> 516 | E12: =IFERROR('Balance sheet row data'!D39,0) -> 650 | F12: =IFERROR('Balance sheet row data'!E39,0) -> 832 | G12: =IFERROR('Balance sheet row data'!F39,0) -> 1075 | H12: =IFERROR('Balance sheet row data'!G39,0) -> 1400
B13: Total Operating Current Assets | D13: =SUM(D10:D12) -> 965 | E13: =SUM(E10:E12) -> 1536 | F13: =SUM(F10:F12) -> 2227 | G13: =SUM(G10:G12) -> 2740 | H13: =SUM(H10:H12) -> 3508
B15: Current Liblities
B16: Trade Payables | D16: =IFERROR('Balance sheet row data'!C12,0) -> 275 | E16: =IFERROR('Balance sheet row data'!D12,0) -> 378 | F16: =IFERROR('Balance sheet row data'!E12,0) -> 665 | G16: =IFERROR('Balance sheet row data'!F12,0) -> 774 | H16: =IFERROR('Balance sheet row data'!G12,0) -> 928
B17: Other liability items | D17: =IFERROR('Balance sheet row data'!C13,0) -> 128 | E17: =IFERROR('Balance sheet row data'!D13,0) -> 213 | F17: =IFERROR('Balance sheet row data'!E13,0) -> 289 | G17: =IFERROR('Balance sheet row data'!F13,0) -> 532 | H17: =IFERROR('Balance sheet row data'!G13,0) -> 671
B18: Total Operating Current Liblities | D18: =SUM(D16:D17) -> 403 | E18: =SUM(E16:E17) -> 591 | F18: =SUM(F16:F17) -> 954 | G18: =SUM(G16:G17) -> 1306 | H18: =SUM(H16:H17) -> 1599
A20: # | B20: Net Working Capital | D20: =D13-D18 -> 562 | E20: =E13-E18 -> 945 | F20: =F13-F18 -> 1273 | G20: =G13-G18 -> 1434 | H20: =H13-H18 -> 1909
B23: Fixed Assets -
B24: Land | D24: =IFERROR('Balance sheet row data'!C17,0) -> 63 | E24: =IFERROR('Balance sheet row data'!D17,0) -> 62 | F24: =IFERROR('Balance sheet row data'!E17,0) -> 77 | G24: =IFERROR('Balance sheet row data'!F17,0) -> 86 | H24: =IFERROR('Balance sheet row data'!G17,0) -> 86
B25: Building | D25: =IFERROR('Balance sheet row data'!C18,0) -> 3117 | E25: =IFERROR('Balance sheet row data'!D18,0) -> 4893 | F25: =IFERROR('Balance sheet row data'!E18,0) -> 4855 | G25: =IFERROR('Balance sheet row data'!F18,0) -> 2162 | H25: =IFERROR('Balance sheet row data'!G18,0) -> 3664
B26: Plant Machinery | D26: =IFERROR('Balance sheet row data'!C19,0) -> 168 | E26: =IFERROR('Balance sheet row data'!D19,0) -> 221 | F26: =IFERROR('Balance sheet row data'!E19,0) -> 287 | G26: =IFERROR('Balance sheet row data'!F19,0) -> 437 | H26: =IFERROR('Balance sheet row data'!G19,0) -> 825
B27: Equipments | D27: =IFERROR('Balance sheet row data'!C20,0) -> 30 | E27: =IFERROR('Balance sheet row data'!D20,0) -> 33 | F27: =IFERROR('Balance sheet row data'!E20,0) -> 39 | G27: =IFERROR('Balance sheet row data'!F20,0) -> 44 | H27: =IFERROR('Balance sheet row data'!G20,0) -> 56
B28: Computers | D28: =IFERROR('Balance sheet row data'!C21,0) -> 59 | E28: =IFERROR('Balance sheet row data'!D21,0) -> 70 | F28: =IFERROR('Balance sheet row data'!E21,0) -> 98 | G28: =IFERROR('Balance sheet row data'!F21,0) -> 112 | H28: =IFERROR('Balance sheet row data'!G21,0) -> 175
B29: Furniture n fittings | D29: =IFERROR('Balance sheet row data'!C22,0) -> 192 | E29: =IFERROR('Balance sheet row data'!D22,0) -> 225 | F29: =IFERROR('Balance sheet row data'!E22,0) -> 328 | G29: =IFERROR('Balance sheet row data'!F22,0) -> 486 | H29: =IFERROR('Balance sheet row data'!G22,0) -> 758
B30: Vehicles | D30: =IFERROR('Balance sheet row data'!C23,0) -> 3 | E30: =IFERROR('Balance sheet row data'!D23,0) -> 3 | F30: =IFERROR('Balance sheet row data'!E23,0) -> 3 | G30: =IFERROR('Balance sheet row data'!F23,0) -> 3 | H30: =IFERROR('Balance sheet row data'!G23,0) -> 4
B31: Intangible Assets | D31: =IFERROR('Balance sheet row data'!C24,0) -> 62 | E31: =IFERROR('Balance sheet row data'!D24,0) -> 62 | F31: =IFERROR('Balance sheet row data'!E24,0) -> 62 | G31: =IFERROR('Balance sheet row data'!F24,0) -> 62 | H31: =IFERROR('Balance sheet row data'!G24,0) -> 62
B32: Other fixed assets | D32: =IFERROR('Balance sheet row data'!C25,0) -> 70 | E32: =IFERROR('Balance sheet row data'!D25,0) -> 78 | F32: =IFERROR('Balance sheet row data'!E25,0) -> 92 | G32: =IFERROR('Balance sheet row data'!F25,0) -> 92 | H32: =IFERROR('Balance sheet row data'!G25,0) -> 98
B33: Gross Block | D33: =SUM(D24:D32) -> 3764 | E33: =SUM(E24:E32) -> 5647 | F33: =SUM(F24:F32) -> 5841 | G33: =SUM(G24:G32) -> 3484 | H33: =SUM(H24:H32) -> 5728
B34: Accumulated Depreciation | D34: =IFERROR('Balance sheet row data'!C27,0) -> 711 | E34: =IFERROR('Balance sheet row data'!D27,0) -> 961 | F34: =IFERROR('Balance sheet row data'!E27,0) -> 1314 | G34: =IFERROR('Balance sheet row data'!F27,0) -> 1035 | H34: =IFERROR('Balance sheet row data'!G27,0) -> 1835
B36: Non- Current Assets | D36: =D33-D34 -> 3053 | E36: =E33-E34 -> 4686 | F36: =F33-F34 -> 4527 | G36: =G33-G34 -> 2449 | H36: =H33-H34 -> 3893
A38: # | B38: Total Capital Invested | D38: =D20+D36 -> 3615 | E38: =E20+E36 -> 5631 | F38: =F20+F36 -> 5800 | G38: =G20+G36 -> 3883 | H38: =H20+H36 -> 5802
B40: EBIT | D40: =IFERROR('Historical Data'!D19,0) -> -143.43 | E40: =IFERROR('Historical Data'!E19,0) -> 283.9 | F40: =IFERROR('Historical Data'!F19,0) -> 620.46 | G40: =IFERROR('Historical Data'!G19,0) -> 1299.58 | H40: =IFERROR('Historical Data'!H19,0) -> 1924.78
B41: Tax Rate | D41: 0.25 | E41: 0.25 | F41: 0.25 | G41: 0.25 | H41: 0.25
B42: EBIT*(1-Tax) | D42: =D40*(1-D41) -> -107.5725 | E42: =E40*(1-E41) -> 212.925 | F42: =F40*(1-F41) -> 465.345 | G42: =G40*(1-G41) -> 974.685 | H42: =H40*(1-H41) -> 1443.585
A44: # | B44: ROIC Rate | D44: =D42/D38 -> -0.029757261 | E44: =E42/E38 -> 0.037812999 | F44: =F42/F38 -> 0.080231897 | G44: =G42/G38 -> 0.25101339 | H44: =H42/H38 -> 0.24880817
B48: Calculation of Reinvestment Rate
B50: Capital Expenditure
B51: Fixed assets purchased | D51: =IFERROR('Historical Data'!D68,0) -> -113 | E51: =IFERROR('Historical Data'!E68,0) -> -271 | F51: =IFERROR('Historical Data'!F68,0) -> -503 | G51: =IFERROR('Historical Data'!G68,0) -> -737 | H51: =IFERROR('Historical Data'!H68,0) -> -1268
B52: Fixed assets sold | D52: =IFERROR('Historical Data'!D69,0) -> 22 | E52: =IFERROR('Historical Data'!E69,0) -> 61 | F52: =IFERROR('Historical Data'!F69,0) -> 280 | G52: =IFERROR('Historical Data'!G69,0) -> 343 | H52: =IFERROR('Historical Data'!H69,0) -> 407
B53: Net Capex | D53: =SUM(D51:D52) -> -91 | E53: =SUM(E51:E52) -> -210 | F53: =SUM(F51:F52) -> -223 | G53: =SUM(G51:G52) -> -394 | H53: =SUM(H51:H52) -> -861
B54: Change in Working Capital | E54: =E20-D20 -> 383 | F54: =F20-E20 -> 328 | G54: =G20-F20 -> 161 | H54: =H20-G20 -> 475
B56: EBIT | D56: =D40 -> -143.43 | E56: =E40 -> 283.9 | F56: =F40 -> 620.46 | G56: =G40 -> 1299.58 | H56: =H40 -> 1924.78
B57: Tax Rate | D57: =D41 -> 0.25 | E57: =E41 -> 0.25 | F57: =F41 -> 0.25 | G57: =G41 -> 0.25 | H57: =H41 -> 0.25
B58: EBIT*(1-Tax) | D58: =D42 -> -107.5725 | E58: =E42 -> 212.925 | F58: =F42 -> 465.345 | G58: =G42 -> 974.685 | H58: =H42 -> 1443.585
...

Sheet Equity valuation
B1: Equity Valuation of Trent Ltd
B3: Calculation of PV of Future Cashflow
B5: Particulars | D5: ='Intresic Growth'!D6 -> 44286 | E5: ='Intresic Growth'!E6 -> 44651 | F5: ='Intresic Growth'!F6 -> 45016 | G5: ='Intresic Growth'!G6 -> 45382 | H5: ='Intresic Growth'!H6 -> 45747
B7: EBIT | D7: =IFERROR('Historical Data'!D19,0) -> -143.43 | E7: =IFERROR('Historical Data'!E19,0) -> 283.9 | F7: =IFERROR('Historical Data'!F19,0) -> 620.46 | G7: =IFERROR('Historical Data'!G19,0) -> 1299.58 | H7: =IFERROR('Historical Data'!H19,0) -> 1924.78
B8: Tax Rate | D8: 0.25 | E8: 0.25 | F8: 0.25 | G8: 0.25 | H8: 0.25
B9: EBIT*(1-Tax Rate) | D9: =D7*(1-D8) -> -107.5725 | E9: =E7*(1-E8) -> 212.925 | F9: =F7*(1-F8) -> 465.345 | G9: =G7*(1-G8) -> 974.685 | H9: =H7*(1-H8) -> 1443.585
B10: Reinvested Amount | D10: =IFERROR('Intresic Growth'!D60,0) -> -91 | E10: =IFERROR('Intresic Growth'!E60,0) -> 173 | F10: =IFERROR('Intresic Growth'!F60,0) -> 105 | G10: =IFERROR('Intresic Growth'!G60,0) -> -233 | H10: =IFERROR('Intresic Growth'!H60,0) -> -386
B11: FCFF | D11: =D9-D10 -> -16.5725 | E11: =E9-E10 -> 39.925 | F11: =F9-F10 -> 360.345 | G11: =G9-G10 -> 1207.685 | H11: =H9-H10 -> 1829.585
B12: Mid Year Convention | E12: 0.5 | F12: =E12+1 -> 1.5 | G12: =F12+1 -> 2.5 | H12: =G12+1 -> 3.5
B13: Discounted Factors | E13: =1/(1+$C$19)^E12 -> 0.9338384 | F13: =1/(1+$C$19)^F12 -> 0.81435765 | G13: =1/(1+$C$19)^G12 -> 0.71016397 | H13: =1/(1+$C$19)^H12 -> 0.61930144
B14: PV of Future CashFlow | E14: =E11*E13 -> 37.283498 | F14: =F11*F13 -> 293.44971 | G14: =G11*G13 -> 857.65437 | H14: =H11*H13 -> 1133.0646
B17: Expected Growth | C17: =IFERROR('Intresic Growth'!H75,0) -> 0.13917426
B18: Terminal Growth | C18: 0.05
B19: WACC | C19: =IFERROR(WACC!J45,0) -> 0.14671778
B22: Calculation of Terminal Value
B24: FCFF (n+1) | D24: =H11*(1+C18) -> 1921.0642
B25: WACC | D25: =C19 -> 0.14671778
B26: Terminal Growth Rate | D26: =C18 -> 0.05
B27: Terminal Value | D27: =D24/(D25-D26) -> 19862.576
B30: Calculation of Equity Value per Share
B32: PV of FCFF | D32: =SUM(E14:H14) -> 2321.4522
B33: PV of Terminal Value | D33: =D27*H13 -> 12300.922
B34: Value of Operating Assets | D34: =SUM(D32:D33) -> 14622.374
B36: Add: Cash | D36: =IFERROR('Balance sheet row data'!G37,0) -> 340
B37: Less: Debt | D37: =IFERROR(SUM('Balance sheet row data'!G8:G9),0) -> 499
B38: Value of Equity | D38: =D34+D36-D37 -> 14463.374
B39: No of Shares | D39: =IFERROR('Data Sheet'!B6,0) -> 35.548747
B41: Share Price Value | D41: =D38/D39 -> 406.86031
B43: Share price | D43: 4275
B44: Discount/Premium | D44: =D43/D41 -> 10.507292 | F44: Note :- The stock looks massively overvalued
